[Sat Jul 19 00:00:01.750920 2025] [mpm_event:notice] [pid 52888:tid 129209350150016] AH00489: Apache/2.4.58 (Ubuntu) OpenSSL/3.0.13 mod_wsgi/5.0.0 Python/3.12 configured -- resuming normal operations
[Sat Jul 19 00:00:01.750954 2025] [core:notice] [pid 52888:tid 129209350150016] AH00094: Command line: '/usr/sbin/apache2'
[Sat Jul 19 09:11:39.327126 2025] [wsgi:error] [pid 54433:tid 129209301194432] [remote 188.102.178.33:12180] ERROR:webApp:Exception on /login [POST]
[Sat Jul 19 09:11:39.327159 2025] [wsgi:error] [pid 54433:tid 129209301194432] [remote 188.102.178.33:12180] Traceback (most recent call last):
[Sat Jul 19 09:11:39.327163 2025] [wsgi:error] [pid 54433:tid 129209301194432] [remote 188.102.178.33:12180]   File "/usr/lib/python3/dist-packages/flask/app.py", line 1463, in wsgi_app
[Sat Jul 19 09:11:39.327167 2025] [wsgi:error] [pid 54433:tid 129209301194432] [remote 188.102.178.33:12180]     response = self.full_dispatch_request()
[Sat Jul 19 09:11:39.327170 2025] [wsgi:error] [pid 54433:tid 129209301194432] [remote 188.102.178.33:12180]                ^^^^^^^^^^^^^^^^^^^^^^^^^^^^
[Sat Jul 19 09:11:39.327174 2025] [wsgi:error] [pid 54433:tid 129209301194432] [remote 188.102.178.33:12180]   File "/usr/lib/python3/dist-packages/flask/app.py", line 872, in full_dispatch_request
[Sat Jul 19 09:11:39.327177 2025] [wsgi:error] [pid 54433:tid 129209301194432] [remote 188.102.178.33:12180]     rv = self.handle_user_exception(e)
[Sat Jul 19 09:11:39.327181 2025] [wsgi:error] [pid 54433:tid 129209301194432] [remote 188.102.178.33:12180]          ^^^^^^^^^^^^^^^^^^^^^^^^^^^^^
[Sat Jul 19 09:11:39.327184 2025] [wsgi:error] [pid 54433:tid 129209301194432] [remote 188.102.178.33:12180]   File "/usr/lib/python3/dist-packages/flask/app.py", line 870, in full_dispatch_request
[Sat Jul 19 09:11:39.327187 2025] [wsgi:error] [pid 54433:tid 129209301194432] [remote 188.102.178.33:12180]     rv = self.dispatch_request()
[Sat Jul 19 09:11:39.327191 2025] [wsgi:error] [pid 54433:tid 129209301194432] [remote 188.102.178.33:12180]          ^^^^^^^^^^^^^^^^^^^^^^^
[Sat Jul 19 09:11:39.327194 2025] [wsgi:error] [pid 54433:tid 129209301194432] [remote 188.102.178.33:12180]   File "/usr/lib/python3/dist-packages/flask/app.py", line 855, in dispatch_request
[Sat Jul 19 09:11:39.327198 2025] [wsgi:error] [pid 54433:tid 129209301194432] [remote 188.102.178.33:12180]     return self.ensure_sync(self.view_functions[rule.endpoint])(**view_args)  # type: ignore[no-any-return]
[Sat Jul 19 09:11:39.327201 2025] [wsgi:error] [pid 54433:tid 129209301194432] [remote 188.102.178.33:12180]            ^^^^^^^^^^^^^^^^^^^^^^^^^^^^^^^^^^^^^^^^^^^^^^^^^^^^^^^^^^^^^^^^^
[Sat Jul 19 09:11:39.327205 2025] [wsgi:error] [pid 54433:tid 129209301194432] [remote 188.102.178.33:12180]   File "/var/www/webApp/webApp/views.py", line 711, in login
[Sat Jul 19 09:11:39.327208 2025] [wsgi:error] [pid 54433:tid 129209301194432] [remote 188.102.178.33:12180]     user = User.query.filter_by(username=request.form['username']).first()
[Sat Jul 19 09:11:39.327212 2025] [wsgi:error] [pid 54433:tid 129209301194432] [remote 188.102.178.33:12180]            ^^^^^^^^^^^^^^^^^^^^^^^^^^^^^^^^^^^^^^^^^^^^^^^^^^^^^^^^^^^^^^^
[Sat Jul 19 09:11:39.327215 2025] [wsgi:error] [pid 54433:tid 129209301194432] [remote 188.102.178.33:12180]   File "/usr/lib/python3/dist-packages/sqlalchemy/orm/query.py", line 2824, in first
[Sat Jul 19 09:11:39.327218 2025] [wsgi:error] [pid 54433:tid 129209301194432] [remote 188.102.178.33:12180]     return self.limit(1)._iter().first()
[Sat Jul 19 09:11:39.327222 2025] [wsgi:error] [pid 54433:tid 129209301194432] [remote 188.102.178.33:12180]            ^^^^^^^^^^^^^^^^^^^^^
[Sat Jul 19 09:11:39.327225 2025] [wsgi:error] [pid 54433:tid 129209301194432] [remote 188.102.178.33:12180]   File "/usr/lib/python3/dist-packages/sqlalchemy/orm/query.py", line 2916, in _iter
[Sat Jul 19 09:11:39.327229 2025] [wsgi:error] [pid 54433:tid 129209301194432] [remote 188.102.178.33:12180]     result = self.session.execute(
[Sat Jul 19 09:11:39.327232 2025] [wsgi:error] [pid 54433:tid 129209301194432] [remote 188.102.178.33:12180]              ^^^^^^^^^^^^^^^^^^^^^
[Sat Jul 19 09:11:39.327245 2025] [wsgi:error] [pid 54433:tid 129209301194432] [remote 188.102.178.33:12180]   File "/usr/lib/python3/dist-packages/sqlalchemy/orm/session.py", line 1705, in execute
[Sat Jul 19 09:11:39.327248 2025] [wsgi:error] [pid 54433:tid 129209301194432] [remote 188.102.178.33:12180]     bind = self.get_bind(**bind_arguments)
[Sat Jul 19 09:11:39.327250 2025] [wsgi:error] [pid 54433:tid 129209301194432] [remote 188.102.178.33:12180]            ^^^^^^^^^^^^^^^^^^^^^^^^^^^^^^^
[Sat Jul 19 09:11:39.327252 2025] [wsgi:error] [pid 54433:tid 129209301194432] [remote 188.102.178.33:12180]   File "/usr/lib/python3/dist-packages/flask_sqlalchemy/session.py", line 53, in get_bind
[Sat Jul 19 09:11:39.327254 2025] [wsgi:error] [pid 54433:tid 129209301194432] [remote 188.102.178.33:12180]     engines = self._db.engines
[Sat Jul 19 09:11:39.327256 2025] [wsgi:error] [pid 54433:tid 129209301194432] [remote 188.102.178.33:12180]               ^^^^^^^^^^^^^^^^
[Sat Jul 19 09:11:39.327258 2025] [wsgi:error] [pid 54433:tid 129209301194432] [remote 188.102.178.33:12180]   File "/usr/lib/python3/dist-packages/flask_sqlalchemy/extension.py", line 639, in engines
[Sat Jul 19 09:11:39.327261 2025] [wsgi:error] [pid 54433:tid 129209301194432] [remote 188.102.178.33:12180]     raise RuntimeError(
[Sat Jul 19 09:11:39.327263 2025] [wsgi:error] [pid 54433:tid 129209301194432] [remote 188.102.178.33:12180] RuntimeError: The current Flask app is not registered with this 'SQLAlchemy' instance. Did you forget to call 'init_app', or did you create multiple 'SQLAlchemy' instances?
[Sat Jul 19 09:11:47.892262 2025] [wsgi:error] [pid 54433:tid 129209301194432] [remote 188.102.178.33:12211] ERROR:webApp:Exception on /login [POST]
[Sat Jul 19 09:11:47.892282 2025] [wsgi:error] [pid 54433:tid 129209301194432] [remote 188.102.178.33:12211] Traceback (most recent call last):
[Sat Jul 19 09:11:47.892285 2025] [wsgi:error] [pid 54433:tid 129209301194432] [remote 188.102.178.33:12211]   File "/usr/lib/python3/dist-packages/flask/app.py", line 1463, in wsgi_app
[Sat Jul 19 09:11:47.892288 2025] [wsgi:error] [pid 54433:tid 129209301194432] [remote 188.102.178.33:12211]     response = self.full_dispatch_request()
[Sat Jul 19 09:11:47.892290 2025] [wsgi:error] [pid 54433:tid 129209301194432] [remote 188.102.178.33:12211]                ^^^^^^^^^^^^^^^^^^^^^^^^^^^^
[Sat Jul 19 09:11:47.892293 2025] [wsgi:error] [pid 54433:tid 129209301194432] [remote 188.102.178.33:12211]   File "/usr/lib/python3/dist-packages/flask/app.py", line 872, in full_dispatch_request
[Sat Jul 19 09:11:47.892295 2025] [wsgi:error] [pid 54433:tid 129209301194432] [remote 188.102.178.33:12211]     rv = self.handle_user_exception(e)
[Sat Jul 19 09:11:47.892297 2025] [wsgi:error] [pid 54433:tid 129209301194432] [remote 188.102.178.33:12211]          ^^^^^^^^^^^^^^^^^^^^^^^^^^^^^
[Sat Jul 19 09:11:47.892299 2025] [wsgi:error] [pid 54433:tid 129209301194432] [remote 188.102.178.33:12211]   File "/usr/lib/python3/dist-packages/flask/app.py", line 870, in full_dispatch_request
[Sat Jul 19 09:11:47.892301 2025] [wsgi:error] [pid 54433:tid 129209301194432] [remote 188.102.178.33:12211]     rv = self.dispatch_request()
[Sat Jul 19 09:11:47.892303 2025] [wsgi:error] [pid 54433:tid 129209301194432] [remote 188.102.178.33:12211]          ^^^^^^^^^^^^^^^^^^^^^^^
[Sat Jul 19 09:11:47.892306 2025] [wsgi:error] [pid 54433:tid 129209301194432] [remote 188.102.178.33:12211]   File "/usr/lib/python3/dist-packages/flask/app.py", line 855, in dispatch_request
[Sat Jul 19 09:11:47.892308 2025] [wsgi:error] [pid 54433:tid 129209301194432] [remote 188.102.178.33:12211]     return self.ensure_sync(self.view_functions[rule.endpoint])(**view_args)  # type: ignore[no-any-return]
[Sat Jul 19 09:11:47.892310 2025] [wsgi:error] [pid 54433:tid 129209301194432] [remote 188.102.178.33:12211]            ^^^^^^^^^^^^^^^^^^^^^^^^^^^^^^^^^^^^^^^^^^^^^^^^^^^^^^^^^^^^^^^^^
[Sat Jul 19 09:11:47.892313 2025] [wsgi:error] [pid 54433:tid 129209301194432] [remote 188.102.178.33:12211]   File "/var/www/webApp/webApp/views.py", line 711, in login
[Sat Jul 19 09:11:47.892325 2025] [wsgi:error] [pid 54433:tid 129209301194432] [remote 188.102.178.33:12211]     user = User.query.filter_by(username=request.form['username']).first()
[Sat Jul 19 09:11:47.892327 2025] [wsgi:error] [pid 54433:tid 129209301194432] [remote 188.102.178.33:12211]            ^^^^^^^^^^^^^^^^^^^^^^^^^^^^^^^^^^^^^^^^^^^^^^^^^^^^^^^^^^^^^^^
[Sat Jul 19 09:11:47.892329 2025] [wsgi:error] [pid 54433:tid 129209301194432] [remote 188.102.178.33:12211]   File "/usr/lib/python3/dist-packages/sqlalchemy/orm/query.py", line 2824, in first
[Sat Jul 19 09:11:47.892332 2025] [wsgi:error] [pid 54433:tid 129209301194432] [remote 188.102.178.33:12211]     return self.limit(1)._iter().first()
[Sat Jul 19 09:11:47.892334 2025] [wsgi:error] [pid 54433:tid 129209301194432] [remote 188.102.178.33:12211]            ^^^^^^^^^^^^^^^^^^^^^
[Sat Jul 19 09:11:47.892336 2025] [wsgi:error] [pid 54433:tid 129209301194432] [remote 188.102.178.33:12211]   File "/usr/lib/python3/dist-packages/sqlalchemy/orm/query.py", line 2916, in _iter
[Sat Jul 19 09:11:47.892338 2025] [wsgi:error] [pid 54433:tid 129209301194432] [remote 188.102.178.33:12211]     result = self.session.execute(
[Sat Jul 19 09:11:47.892340 2025] [wsgi:error] [pid 54433:tid 129209301194432] [remote 188.102.178.33:12211]              ^^^^^^^^^^^^^^^^^^^^^
[Sat Jul 19 09:11:47.892342 2025] [wsgi:error] [pid 54433:tid 129209301194432] [remote 188.102.178.33:12211]   File "/usr/lib/python3/dist-packages/sqlalchemy/orm/session.py", line 1705, in execute
[Sat Jul 19 09:11:47.892344 2025] [wsgi:error] [pid 54433:tid 129209301194432] [remote 188.102.178.33:12211]     bind = self.get_bind(**bind_arguments)
[Sat Jul 19 09:11:47.892347 2025] [wsgi:error] [pid 54433:tid 129209301194432] [remote 188.102.178.33:12211]            ^^^^^^^^^^^^^^^^^^^^^^^^^^^^^^^
[Sat Jul 19 09:11:47.892349 2025] [wsgi:error] [pid 54433:tid 129209301194432] [remote 188.102.178.33:12211]   File "/usr/lib/python3/dist-packages/flask_sqlalchemy/session.py", line 53, in get_bind
[Sat Jul 19 09:11:47.892351 2025] [wsgi:error] [pid 54433:tid 129209301194432] [remote 188.102.178.33:12211]     engines = self._db.engines
[Sat Jul 19 09:11:47.892353 2025] [wsgi:error] [pid 54433:tid 129209301194432] [remote 188.102.178.33:12211]               ^^^^^^^^^^^^^^^^
[Sat Jul 19 09:11:47.892355 2025] [wsgi:error] [pid 54433:tid 129209301194432] [remote 188.102.178.33:12211]   File "/usr/lib/python3/dist-packages/flask_sqlalchemy/extension.py", line 639, in engines
[Sat Jul 19 09:11:47.892357 2025] [wsgi:error] [pid 54433:tid 129209301194432] [remote 188.102.178.33:12211]     raise RuntimeError(
[Sat Jul 19 09:11:47.892360 2025] [wsgi:error] [pid 54433:tid 129209301194432] [remote 188.102.178.33:12211] RuntimeError: The current Flask app is not registered with this 'SQLAlchemy' instance. Did you forget to call 'init_app', or did you create multiple 'SQLAlchemy' instances?
[Sat Jul 19 10:11:14.205171 2025] [wsgi:error] [pid 54433:tid 129209200481984] [remote 89.244.85.32:22922] ERROR:webApp:Exception on /login [POST]
[Sat Jul 19 10:11:14.205205 2025] [wsgi:error] [pid 54433:tid 129209200481984] [remote 89.244.85.32:22922] Traceback (most recent call last):
[Sat Jul 19 10:11:14.205211 2025] [wsgi:error] [pid 54433:tid 129209200481984] [remote 89.244.85.32:22922]   File "/usr/lib/python3/dist-packages/flask/app.py", line 1463, in wsgi_app
[Sat Jul 19 10:11:14.205216 2025] [wsgi:error] [pid 54433:tid 129209200481984] [remote 89.244.85.32:22922]     response = self.full_dispatch_request()
[Sat Jul 19 10:11:14.205221 2025] [wsgi:error] [pid 54433:tid 129209200481984] [remote 89.244.85.32:22922]                ^^^^^^^^^^^^^^^^^^^^^^^^^^^^
[Sat Jul 19 10:11:14.205225 2025] [wsgi:error] [pid 54433:tid 129209200481984] [remote 89.244.85.32:22922]   File "/usr/lib/python3/dist-packages/flask/app.py", line 872, in full_dispatch_request
[Sat Jul 19 10:11:14.205230 2025] [wsgi:error] [pid 54433:tid 129209200481984] [remote 89.244.85.32:22922]     rv = self.handle_user_exception(e)
[Sat Jul 19 10:11:14.205245 2025] [wsgi:error] [pid 54433:tid 129209200481984] [remote 89.244.85.32:22922]          ^^^^^^^^^^^^^^^^^^^^^^^^^^^^^
[Sat Jul 19 10:11:14.205248 2025] [wsgi:error] [pid 54433:tid 129209200481984] [remote 89.244.85.32:22922]   File "/usr/lib/python3/dist-packages/flask/app.py", line 870, in full_dispatch_request
[Sat Jul 19 10:11:14.205251 2025] [wsgi:error] [pid 54433:tid 129209200481984] [remote 89.244.85.32:22922]     rv = self.dispatch_request()
[Sat Jul 19 10:11:14.205254 2025] [wsgi:error] [pid 54433:tid 129209200481984] [remote 89.244.85.32:22922]          ^^^^^^^^^^^^^^^^^^^^^^^
[Sat Jul 19 10:11:14.205257 2025] [wsgi:error] [pid 54433:tid 129209200481984] [remote 89.244.85.32:22922]   File "/usr/lib/python3/dist-packages/flask/app.py", line 855, in dispatch_request
[Sat Jul 19 10:11:14.205260 2025] [wsgi:error] [pid 54433:tid 129209200481984] [remote 89.244.85.32:22922]     return self.ensure_sync(self.view_functions[rule.endpoint])(**view_args)  # type: ignore[no-any-return]
[Sat Jul 19 10:11:14.205263 2025] [wsgi:error] [pid 54433:tid 129209200481984] [remote 89.244.85.32:22922]            ^^^^^^^^^^^^^^^^^^^^^^^^^^^^^^^^^^^^^^^^^^^^^^^^^^^^^^^^^^^^^^^^^
[Sat Jul 19 10:11:14.205266 2025] [wsgi:error] [pid 54433:tid 129209200481984] [remote 89.244.85.32:22922]   File "/var/www/webApp/webApp/views.py", line 711, in login
[Sat Jul 19 10:11:14.205270 2025] [wsgi:error] [pid 54433:tid 129209200481984] [remote 89.244.85.32:22922]     user = User.query.filter_by(username=request.form['username']).first()
[Sat Jul 19 10:11:14.205273 2025] [wsgi:error] [pid 54433:tid 129209200481984] [remote 89.244.85.32:22922]            ^^^^^^^^^^^^^^^^^^^^^^^^^^^^^^^^^^^^^^^^^^^^^^^^^^^^^^^^^^^^^^^
[Sat Jul 19 10:11:14.205276 2025] [wsgi:error] [pid 54433:tid 129209200481984] [remote 89.244.85.32:22922]   File "/usr/lib/python3/dist-packages/sqlalchemy/orm/query.py", line 2824, in first
[Sat Jul 19 10:11:14.205279 2025] [wsgi:error] [pid 54433:tid 129209200481984] [remote 89.244.85.32:22922]     return self.limit(1)._iter().first()
[Sat Jul 19 10:11:14.205282 2025] [wsgi:error] [pid 54433:tid 129209200481984] [remote 89.244.85.32:22922]            ^^^^^^^^^^^^^^^^^^^^^
[Sat Jul 19 10:11:14.205285 2025] [wsgi:error] [pid 54433:tid 129209200481984] [remote 89.244.85.32:22922]   File "/usr/lib/python3/dist-packages/sqlalchemy/orm/query.py", line 2916, in _iter
[Sat Jul 19 10:11:14.205288 2025] [wsgi:error] [pid 54433:tid 129209200481984] [remote 89.244.85.32:22922]     result = self.session.execute(
[Sat Jul 19 10:11:14.205291 2025] [wsgi:error] [pid 54433:tid 129209200481984] [remote 89.244.85.32:22922]              ^^^^^^^^^^^^^^^^^^^^^
[Sat Jul 19 10:11:14.205294 2025] [wsgi:error] [pid 54433:tid 129209200481984] [remote 89.244.85.32:22922]   File "/usr/lib/python3/dist-packages/sqlalchemy/orm/session.py", line 1705, in execute
[Sat Jul 19 10:11:14.205297 2025] [wsgi:error] [pid 54433:tid 129209200481984] [remote 89.244.85.32:22922]     bind = self.get_bind(**bind_arguments)
[Sat Jul 19 10:11:14.205300 2025] [wsgi:error] [pid 54433:tid 129209200481984] [remote 89.244.85.32:22922]            ^^^^^^^^^^^^^^^^^^^^^^^^^^^^^^^
[Sat Jul 19 10:11:14.205303 2025] [wsgi:error] [pid 54433:tid 129209200481984] [remote 89.244.85.32:22922]   File "/usr/lib/python3/dist-packages/flask_sqlalchemy/session.py", line 53, in get_bind
[Sat Jul 19 10:11:14.205306 2025] [wsgi:error] [pid 54433:tid 129209200481984] [remote 89.244.85.32:22922]     engines = self._db.engines
[Sat Jul 19 10:11:14.205309 2025] [wsgi:error] [pid 54433:tid 129209200481984] [remote 89.244.85.32:22922]               ^^^^^^^^^^^^^^^^
[Sat Jul 19 10:11:14.205311 2025] [wsgi:error] [pid 54433:tid 129209200481984] [remote 89.244.85.32:22922]   File "/usr/lib/python3/dist-packages/flask_sqlalchemy/extension.py", line 639, in engines
[Sat Jul 19 10:11:14.205315 2025] [wsgi:error] [pid 54433:tid 129209200481984] [remote 89.244.85.32:22922]     raise RuntimeError(
[Sat Jul 19 10:11:14.205318 2025] [wsgi:error] [pid 54433:tid 129209200481984] [remote 89.244.85.32:22922] RuntimeError: The current Flask app is not registered with this 'SQLAlchemy' instance. Did you forget to call 'init_app', or did you create multiple 'SQLAlchemy' instances?
